<?xml version="1.0"?>
<robot name="my_robot" xmlns:xacro="http://www.ros.org/wiki/xacro">
    <xacro:include filename="inertial_macros.xacro" />

    <!-- 颜色定义 -->
    <material name="white">
        <color rgba="1 1 1 1" />
    </material>

    <material name="orange">
        <color rgba="1 0.3 0.1 1" />
    </material>

    <material name="blue">
        <color rgba="0.2 0.2 1 1" />
    </material>

    <material name="black">
        <color rgba="0 0 0 1" />
    </material>

    <material name="red">
        <color rgba="1 0 0 1" />
    </material>

    <!-- 车身结构 -->
    <link name="base_link">
        <visual>
            <origin xyz="-0.0275 0 0.0479" rpy="0 0 0" />
            <geometry>
                <box size="0.123 0.142 0.0958" />
            </geometry>
            <material name="white" />
        </visual>
        <collision>
            <origin xyz="-0.0275 0 0.0479" rpy="0 0 0" />
            <geometry>
                <box size="0.123 0.142 0.0958" />
            </geometry>
        </collision>
        <xacro:inertial_box mass="1.5" x="0.123" y="0.142" z="0.0958">
            <origin xyz="-0.05 0 0.0479" rpy="0 0 0" />
        </xacro:inertial_box>
    </link>

    <!-- BASE_FOOTPRINT -->

    <joint name="base_footprint_joint" type="fixed">
        <parent link="base_footprint" />
        <child link="base_link" />
        <!-- <origin xyz="0 0 0.05" rpy="0 0 0" /> -->
        <origin xyz="0 0 0.012" rpy="0 0 0" />
    </joint>

    <link name="base_footprint">
    </link>

    <!-- 左轮 -->
    <joint name="left_wheel_joint" type="continuous">
        <parent link="base_link" />
        <child link="left_wheel" />
        <origin xyz="0.0 0.0658 0.0215" rpy="-${pi/2} 0.0 0.0" />
        <axis xyz="0.0 0.0 1.0" />
    </joint>

    <link name="left_wheel">
        <visual>
            <geometry>
                <cylinder radius="0.0335" length="0.031" />
            </geometry>
            <material name="blue" />
        </visual>
        <collision>
            <geometry>
                <cylinder radius="0.0335" length="0.031" />
            </geometry>
        </collision>
        <xacro:inertial_cylinder mass="0.1" length="0.031" radius="0.0335">
            <origin xyz="0 0 0" rpy="0 0 0" />
        </xacro:inertial_cylinder>
    </link>

    <gazebo reference="left_wheel">
        <mu1>1.0</mu1>
        <mu2>1.0</mu2>
        <kp>1000000.0</kp>
        <kd>100.0</kd>
        <minDepth>0.001</minDepth>
        <maxVel>0.1</maxVel>
        <fdir1>1 0 0</fdir1>
        <material>Gazebo/Blue</material>
    </gazebo>

    <!-- 右轮 -->
    <joint name="right_wheel_joint" type="continuous">
        <parent link="base_link" />
        <child link="right_wheel" />
        <origin xyz="0.0 -0.0658 0.0215" rpy="${pi/2} 0.0 0.0" />
        <axis xyz="0.0 0.0 -1.0" />
    </joint>

    <link name="right_wheel">
        <visual>
            <geometry>
                <cylinder radius="0.0335" length="0.031" />
            </geometry>
            <material name="blue" />
        </visual>
        <collision>
            <geometry>
                <cylinder radius="0.0335" length="0.031" />
            </geometry>
        </collision>
        <xacro:inertial_cylinder mass="0.1" length="0.031" radius="0.0335">
            <origin xyz="0 0 0" rpy="0 0 0" />
        </xacro:inertial_cylinder>
    </link>

    <gazebo reference="right_wheel">
        <mu1>1.0</mu1>
        <mu2>1.0</mu2>
        <kp>1000000.0</kp>
        <kd>100.0</kd>
        <minDepth>0.001</minDepth>
        <maxVel>0.1</maxVel>
        <fdir1>1 0 0</fdir1>
        <material>Gazebo/Blue</material>
    </gazebo>

    <!-- 后辅助轮 -->
    <joint name="caster_back_joint" type="fixed">
        <parent link="base_link" />
        <child link="caster_back_wheel" />
        <origin xyz="-0.06445 0 0.008" rpy="0 0 0" />
    </joint>

    <link name="caster_back_wheel">
        <visual>
            <geometry>
                <sphere radius="0.02" />
            </geometry>
            <material name="black" />
        </visual>
        <collision>
            <geometry>
                <sphere radius="0.02" />
            </geometry>
        </collision>
        <xacro:inertial_sphere mass="0.1" radius="0.02">
            <origin xyz="0 0 0" rpy="0 0 0" />
        </xacro:inertial_sphere>
    </link>

    <gazebo reference="caster_back_wheel">
        <mu1>0.0001</mu1>
        <mu2>0.0001</mu2>
        <kp>1000000.0</kp>
        <kd>100.0</kd>
        <minDepth>0.001</minDepth>
        <maxVel>1.0</maxVel>
        <material>Gazebo/Black</material>
    </gazebo>

</robot>